Exception on /login [GET]
Traceback (most recent call last):
  File "/usr/local/lib/python2.7/dist-packages/flask/app.py", line 1817, in wsgi_app
    response = self.full_dispatch_request()
  File "/usr/local/lib/python2.7/dist-packages/flask/app.py", line 1477, in full_dispatch_request
    rv = self.handle_user_exception(e)
  File "/usr/local/lib/python2.7/dist-packages/flask/app.py", line 1381, in handle_user_exception
    reraise(exc_type, exc_value, tb)
  File "/usr/local/lib/python2.7/dist-packages/flask/app.py", line 1475, in full_dispatch_request
    rv = self.dispatch_request()
  File "/usr/local/lib/python2.7/dist-packages/flask/app.py", line 1461, in dispatch_request
    return self.view_functions[rule.endpoint](**req.view_args)
  File "/var/www/html/study4share/apps/controllers.py", line 67, in login
    return render_template('login.html', loginform=loginform, joinform=joinform, modal_open=False)
  File "/usr/local/lib/python2.7/dist-packages/flask/templating.py", line 127, in render_template
    return _render(ctx.app.jinja_env.get_or_select_template(template_name_or_list),
  File "/usr/local/lib/python2.7/dist-packages/jinja2/environment.py", line 830, in get_or_select_template
    return self.get_template(template_name_or_list, parent, globals)
  File "/usr/local/lib/python2.7/dist-packages/jinja2/environment.py", line 791, in get_template
    return self._load_template(name, self.make_globals(globals))
  File "/usr/local/lib/python2.7/dist-packages/jinja2/environment.py", line 765, in _load_template
    template = self.loader.load(self, name, globals)
  File "/usr/local/lib/python2.7/dist-packages/jinja2/loaders.py", line 125, in load
    code = environment.compile(source, name, filename)
  File "/usr/local/lib/python2.7/dist-packages/jinja2/environment.py", line 554, in compile
    self.handle_exception(exc_info, source_hint=source)
  File "/usr/local/lib/python2.7/dist-packages/jinja2/environment.py", line 742, in handle_exception
    reraise(exc_type, exc_value, tb)
  File "/var/www/html/study4share/apps/templates/login.html", line 129, in template
    {{loginform.password(class="form-contorl", placeholder="������������������������" id="password")}}
TemplateSyntaxError: expected token ',', got 'id'
Exception on /login [POST]
Traceback (most recent call last):
  File "/usr/local/lib/python2.7/dist-packages/flask/app.py", line 1817, in wsgi_app
    response = self.full_dispatch_request()
  File "/usr/local/lib/python2.7/dist-packages/flask/app.py", line 1477, in full_dispatch_request
    rv = self.handle_user_exception(e)
  File "/usr/local/lib/python2.7/dist-packages/flask/app.py", line 1381, in handle_user_exception
    reraise(exc_type, exc_value, tb)
  File "/usr/local/lib/python2.7/dist-packages/flask/app.py", line 1475, in full_dispatch_request
    rv = self.dispatch_request()
  File "/usr/local/lib/python2.7/dist-packages/flask/app.py", line 1461, in dispatch_request
    return self.view_functions[rule.endpoint](**req.view_args)
  File "/var/www/html/study4share/apps/controllers.py", line 59, in login
    if check_password_hash(user.password, loginform.password.data):
AttributeError: 'User' object has no attribute 'password'
Exception on /join [POST]
Traceback (most recent call last):
  File "/usr/local/lib/python2.7/dist-packages/flask/app.py", line 1817, in wsgi_app
    response = self.full_dispatch_request()
  File "/usr/local/lib/python2.7/dist-packages/flask/app.py", line 1477, in full_dispatch_request
    rv = self.handle_user_exception(e)
  File "/usr/local/lib/python2.7/dist-packages/flask/app.py", line 1381, in handle_user_exception
    reraise(exc_type, exc_value, tb)
  File "/usr/local/lib/python2.7/dist-packages/flask/app.py", line 1475, in full_dispatch_request
    rv = self.dispatch_request()
  File "/usr/local/lib/python2.7/dist-packages/flask/app.py", line 1461, in dispatch_request
    return self.view_functions[rule.endpoint](**req.view_args)
  File "/var/www/html/study4share/apps/controllers.py", line 79, in join
    if User.query.get(joinform.id.data):
  File "/usr/local/lib/python2.7/dist-packages/flask_sqlalchemy/__init__.py", line 452, in __get__
    mapper = orm.class_mapper(type)
  File "/usr/local/lib/python2.7/dist-packages/sqlalchemy/orm/base.py", line 412, in class_mapper
    mapper = _inspect_mapped_class(class_, configure=configure)
  File "/usr/local/lib/python2.7/dist-packages/sqlalchemy/orm/base.py", line 391, in _inspect_mapped_class
    mapper._configure_all()
  File "/usr/local/lib/python2.7/dist-packages/sqlalchemy/orm/mapper.py", line 1156, in _configure_all
    configure_mappers()
  File "/usr/local/lib/python2.7/dist-packages/sqlalchemy/orm/mapper.py", line 2598, in configure_mappers
    mapper._post_configure_properties()
  File "/usr/local/lib/python2.7/dist-packages/sqlalchemy/orm/mapper.py", line 1696, in _post_configure_properties
    prop.init()
  File "/usr/local/lib/python2.7/dist-packages/sqlalchemy/orm/interfaces.py", line 144, in init
    self.do_init()
  File "/usr/local/lib/python2.7/dist-packages/sqlalchemy/orm/relationships.py", line 1550, in do_init
    self._process_dependent_arguments()
  File "/usr/local/lib/python2.7/dist-packages/sqlalchemy/orm/relationships.py", line 1574, in _process_dependent_arguments
    setattr(self, attr, attr_value())
  File "/usr/local/lib/python2.7/dist-packages/sqlalchemy/ext/declarative/clsregistry.py", line 283, in __call__
    (self.prop.parent, self.arg, n.args[0], self.cls)
InvalidRequestError: When initializing mapper Mapper|Solution|solution, expression 'Solution.prob_id==Question.id' failed to locate a name ("name 'Question' is not defined"). If this is a class name, consider adding this relationship() to the <class 'apps.models.Solution'> class after both dependent classes have been defined.
Exception on /login [POST]
Traceback (most recent call last):
  File "/usr/local/lib/python2.7/dist-packages/flask/app.py", line 1817, in wsgi_app
    response = self.full_dispatch_request()
  File "/usr/local/lib/python2.7/dist-packages/flask/app.py", line 1477, in full_dispatch_request
    rv = self.handle_user_exception(e)
  File "/usr/local/lib/python2.7/dist-packages/flask/app.py", line 1381, in handle_user_exception
    reraise(exc_type, exc_value, tb)
  File "/usr/local/lib/python2.7/dist-packages/flask/app.py", line 1475, in full_dispatch_request
    rv = self.dispatch_request()
  File "/usr/local/lib/python2.7/dist-packages/flask/app.py", line 1461, in dispatch_request
    return self.view_functions[rule.endpoint](**req.view_args)
  File "/var/www/html/study4share/apps/controllers.py", line 58, in login
    return user.pw, generate_password_hash(loginform.password.data)
UnboundLocalError: local variable 'user' referenced before assignment
Exception on /login [POST]
Traceback (most recent call last):
  File "/usr/local/lib/python2.7/dist-packages/flask/app.py", line 1817, in wsgi_app
    response = self.full_dispatch_request()
  File "/usr/local/lib/python2.7/dist-packages/flask/app.py", line 1477, in full_dispatch_request
    rv = self.handle_user_exception(e)
  File "/usr/local/lib/python2.7/dist-packages/flask/app.py", line 1381, in handle_user_exception
    reraise(exc_type, exc_value, tb)
  File "/usr/local/lib/python2.7/dist-packages/flask/app.py", line 1475, in full_dispatch_request
    rv = self.dispatch_request()
  File "/usr/local/lib/python2.7/dist-packages/flask/app.py", line 1461, in dispatch_request
    return self.view_functions[rule.endpoint](**req.view_args)
  File "/var/www/html/study4share/apps/controllers.py", line 58, in login
    return user.pw + " <br> " +  generate_password_hash(loginform.password.data)
UnboundLocalError: local variable 'user' referenced before assignment
