Exception on /main [POST]
Traceback (most recent call last):
  File "/usr/local/lib/python2.7/dist-packages/flask/app.py", line 1817, in wsgi_app
    response = self.full_dispatch_request()
  File "/usr/local/lib/python2.7/dist-packages/flask/app.py", line 1477, in full_dispatch_request
    rv = self.handle_user_exception(e)
  File "/usr/local/lib/python2.7/dist-packages/flask/app.py", line 1381, in handle_user_exception
    reraise(exc_type, exc_value, tb)
  File "/usr/local/lib/python2.7/dist-packages/flask/app.py", line 1475, in full_dispatch_request
    rv = self.dispatch_request()
  File "/usr/local/lib/python2.7/dist-packages/flask/app.py", line 1461, in dispatch_request
    return self.view_functions[rule.endpoint](**req.view_args)
  File "/usr/local/lib/python2.7/dist-packages/flask_login.py", line 758, in decorated_view
    return func(*args, **kwargs)
  File "/var/www/html/study4share/apps/controllers.py", line 119, in main
    return render_template('main.html', form=form, tags=tags, mpmodal_open=True, textcolor=textcolor)
  File "/usr/local/lib/python2.7/dist-packages/flask/templating.py", line 128, in render_template
    context, ctx.app)
  File "/usr/local/lib/python2.7/dist-packages/flask/templating.py", line 110, in _render
    rv = template.render(context)
  File "/usr/local/lib/python2.7/dist-packages/jinja2/environment.py", line 969, in render
    return self.environment.handle_exception(exc_info, True)
  File "/usr/local/lib/python2.7/dist-packages/jinja2/environment.py", line 742, in handle_exception
    reraise(exc_type, exc_value, tb)
  File "/var/www/html/study4share/apps/templates/main.html", line 1, in top-level template code
    {% extends "base.html" %}
  File "/var/www/html/study4share/apps/templates/base.html", line 66, in top-level template code
    {% block content %}{% endblock %}
  File "/var/www/html/study4share/apps/templates/main.html", line 61, in block "content"
    {{message}}
  File "/usr/local/lib/python2.7/dist-packages/markupsafe/_native.py", line 22, in escape
    return Markup(text_type(s)
UnicodeDecodeError: 'ascii' codec can't decode byte 0xeb in position 1: ordinal not in range(128)
Exception on /update_problem/103 [POST]
Traceback (most recent call last):
  File "/usr/local/lib/python2.7/dist-packages/flask/app.py", line 1817, in wsgi_app
    response = self.full_dispatch_request()
  File "/usr/local/lib/python2.7/dist-packages/flask/app.py", line 1477, in full_dispatch_request
    rv = self.handle_user_exception(e)
  File "/usr/local/lib/python2.7/dist-packages/flask/app.py", line 1381, in handle_user_exception
    reraise(exc_type, exc_value, tb)
  File "/usr/local/lib/python2.7/dist-packages/flask/app.py", line 1475, in full_dispatch_request
    rv = self.dispatch_request()
  File "/usr/local/lib/python2.7/dist-packages/flask/app.py", line 1461, in dispatch_request
    return self.view_functions[rule.endpoint](**req.view_args)
  File "/usr/local/lib/python2.7/dist-packages/flask_login.py", line 758, in decorated_view
    return func(*args, **kwargs)
  File "/var/www/html/study4share/apps/controllers.py", line 341, in update_problem
    probForm.populate_obj(problem)
  File "/usr/local/lib/python2.7/dist-packages/wtforms/form.py", line 96, in populate_obj
    field.populate_obj(obj, name)
  File "/usr/local/lib/python2.7/dist-packages/wtforms/fields/core.py", line 323, in populate_obj
    setattr(obj, name, self.data)
  File "/usr/local/lib/python2.7/dist-packages/sqlalchemy/orm/attributes.py", line 226, in __set__
    instance_dict(instance), value, None)
  File "/usr/local/lib/python2.7/dist-packages/sqlalchemy/orm/attributes.py", line 812, in set
    value = self.fire_replace_event(state, dict_, value, old, initiator)
  File "/usr/local/lib/python2.7/dist-packages/sqlalchemy/orm/attributes.py", line 832, in fire_replace_event
    state, value, previous, initiator or self._replace_token)
  File "/usr/local/lib/python2.7/dist-packages/sqlalchemy/orm/unitofwork.py", line 84, in set_
    newvalue_state = attributes.instance_state(newvalue)
AttributeError: 'unicode' object has no attribute '_sa_instance_state'
Exception on /update_problem/225 [POST]
Traceback (most recent call last):
  File "/usr/local/lib/python2.7/dist-packages/flask/app.py", line 1817, in wsgi_app
    response = self.full_dispatch_request()
  File "/usr/local/lib/python2.7/dist-packages/flask/app.py", line 1477, in full_dispatch_request
    rv = self.handle_user_exception(e)
  File "/usr/local/lib/python2.7/dist-packages/flask/app.py", line 1381, in handle_user_exception
    reraise(exc_type, exc_value, tb)
  File "/usr/local/lib/python2.7/dist-packages/flask/app.py", line 1475, in full_dispatch_request
    rv = self.dispatch_request()
  File "/usr/local/lib/python2.7/dist-packages/flask/app.py", line 1461, in dispatch_request
    return self.view_functions[rule.endpoint](**req.view_args)
  File "/usr/local/lib/python2.7/dist-packages/flask_login.py", line 758, in decorated_view
    return func(*args, **kwargs)
  File "/var/www/html/study4share/apps/controllers.py", line 341, in update_problem
    probForm.populate_obj(problem)
  File "/usr/local/lib/python2.7/dist-packages/wtforms/form.py", line 96, in populate_obj
    field.populate_obj(obj, name)
  File "/usr/local/lib/python2.7/dist-packages/wtforms/fields/core.py", line 323, in populate_obj
    setattr(obj, name, self.data)
  File "/usr/local/lib/python2.7/dist-packages/sqlalchemy/orm/attributes.py", line 226, in __set__
    instance_dict(instance), value, None)
  File "/usr/local/lib/python2.7/dist-packages/sqlalchemy/orm/attributes.py", line 812, in set
    value = self.fire_replace_event(state, dict_, value, old, initiator)
  File "/usr/local/lib/python2.7/dist-packages/sqlalchemy/orm/attributes.py", line 832, in fire_replace_event
    state, value, previous, initiator or self._replace_token)
  File "/usr/local/lib/python2.7/dist-packages/sqlalchemy/orm/unitofwork.py", line 84, in set_
    newvalue_state = attributes.instance_state(newvalue)
AttributeError: 'unicode' object has no attribute '_sa_instance_state'
Exception on /update_problem/103 [POST]
Traceback (most recent call last):
  File "/usr/local/lib/python2.7/dist-packages/flask/app.py", line 1817, in wsgi_app
    response = self.full_dispatch_request()
  File "/usr/local/lib/python2.7/dist-packages/flask/app.py", line 1477, in full_dispatch_request
    rv = self.handle_user_exception(e)
  File "/usr/local/lib/python2.7/dist-packages/flask/app.py", line 1381, in handle_user_exception
    reraise(exc_type, exc_value, tb)
  File "/usr/local/lib/python2.7/dist-packages/flask/app.py", line 1475, in full_dispatch_request
    rv = self.dispatch_request()
  File "/usr/local/lib/python2.7/dist-packages/flask/app.py", line 1461, in dispatch_request
    return self.view_functions[rule.endpoint](**req.view_args)
  File "/usr/local/lib/python2.7/dist-packages/flask_login.py", line 758, in decorated_view
    return func(*args, **kwargs)
  File "/var/www/html/study4share/apps/controllers.py", line 341, in update_problem
    probForm.populate_obj(problem)
  File "/usr/local/lib/python2.7/dist-packages/wtforms/form.py", line 96, in populate_obj
    field.populate_obj(obj, name)
  File "/usr/local/lib/python2.7/dist-packages/wtforms/fields/core.py", line 323, in populate_obj
    setattr(obj, name, self.data)
  File "/usr/local/lib/python2.7/dist-packages/sqlalchemy/orm/attributes.py", line 226, in __set__
    instance_dict(instance), value, None)
  File "/usr/local/lib/python2.7/dist-packages/sqlalchemy/orm/attributes.py", line 812, in set
    value = self.fire_replace_event(state, dict_, value, old, initiator)
  File "/usr/local/lib/python2.7/dist-packages/sqlalchemy/orm/attributes.py", line 832, in fire_replace_event
    state, value, previous, initiator or self._replace_token)
  File "/usr/local/lib/python2.7/dist-packages/sqlalchemy/orm/unitofwork.py", line 84, in set_
    newvalue_state = attributes.instance_state(newvalue)
AttributeError: 'unicode' object has no attribute '_sa_instance_state'
Exception on /update_problem/233 [POST]
Traceback (most recent call last):
  File "/usr/local/lib/python2.7/dist-packages/flask/app.py", line 1817, in wsgi_app
    response = self.full_dispatch_request()
  File "/usr/local/lib/python2.7/dist-packages/flask/app.py", line 1477, in full_dispatch_request
    rv = self.handle_user_exception(e)
  File "/usr/local/lib/python2.7/dist-packages/flask/app.py", line 1381, in handle_user_exception
    reraise(exc_type, exc_value, tb)
  File "/usr/local/lib/python2.7/dist-packages/flask/app.py", line 1475, in full_dispatch_request
    rv = self.dispatch_request()
  File "/usr/local/lib/python2.7/dist-packages/flask/app.py", line 1461, in dispatch_request
    return self.view_functions[rule.endpoint](**req.view_args)
  File "/usr/local/lib/python2.7/dist-packages/flask_login.py", line 758, in decorated_view
    return func(*args, **kwargs)
  File "/var/www/html/study4share/apps/controllers.py", line 342, in update_problem
    probForm.populate_obj(problem)
  File "/usr/local/lib/python2.7/dist-packages/wtforms/form.py", line 96, in populate_obj
    field.populate_obj(obj, name)
  File "/usr/local/lib/python2.7/dist-packages/wtforms/fields/core.py", line 323, in populate_obj
    setattr(obj, name, self.data)
  File "/usr/local/lib/python2.7/dist-packages/sqlalchemy/orm/attributes.py", line 226, in __set__
    instance_dict(instance), value, None)
  File "/usr/local/lib/python2.7/dist-packages/sqlalchemy/orm/attributes.py", line 812, in set
    value = self.fire_replace_event(state, dict_, value, old, initiator)
  File "/usr/local/lib/python2.7/dist-packages/sqlalchemy/orm/attributes.py", line 832, in fire_replace_event
    state, value, previous, initiator or self._replace_token)
  File "/usr/local/lib/python2.7/dist-packages/sqlalchemy/orm/unitofwork.py", line 84, in set_
    newvalue_state = attributes.instance_state(newvalue)
AttributeError: 'unicode' object has no attribute '_sa_instance_state'
Exception on /update_problem/233 [POST]
Traceback (most recent call last):
  File "/usr/local/lib/python2.7/dist-packages/flask/app.py", line 1817, in wsgi_app
    response = self.full_dispatch_request()
  File "/usr/local/lib/python2.7/dist-packages/flask/app.py", line 1477, in full_dispatch_request
    rv = self.handle_user_exception(e)
  File "/usr/local/lib/python2.7/dist-packages/flask/app.py", line 1381, in handle_user_exception
    reraise(exc_type, exc_value, tb)
  File "/usr/local/lib/python2.7/dist-packages/flask/app.py", line 1475, in full_dispatch_request
    rv = self.dispatch_request()
  File "/usr/local/lib/python2.7/dist-packages/flask/app.py", line 1461, in dispatch_request
    return self.view_functions[rule.endpoint](**req.view_args)
  File "/usr/local/lib/python2.7/dist-packages/flask_login.py", line 758, in decorated_view
    return func(*args, **kwargs)
  File "/var/www/html/study4share/apps/controllers.py", line 342, in update_problem
    probForm.populate_obj(problem)
  File "/usr/local/lib/python2.7/dist-packages/wtforms/form.py", line 96, in populate_obj
    field.populate_obj(obj, name)
  File "/usr/local/lib/python2.7/dist-packages/wtforms/fields/core.py", line 323, in populate_obj
    setattr(obj, name, self.data)
  File "/usr/local/lib/python2.7/dist-packages/sqlalchemy/orm/attributes.py", line 226, in __set__
    instance_dict(instance), value, None)
  File "/usr/local/lib/python2.7/dist-packages/sqlalchemy/orm/attributes.py", line 812, in set
    value = self.fire_replace_event(state, dict_, value, old, initiator)
  File "/usr/local/lib/python2.7/dist-packages/sqlalchemy/orm/attributes.py", line 832, in fire_replace_event
    state, value, previous, initiator or self._replace_token)
  File "/usr/local/lib/python2.7/dist-packages/sqlalchemy/orm/unitofwork.py", line 84, in set_
    newvalue_state = attributes.instance_state(newvalue)
AttributeError: 'unicode' object has no attribute '_sa_instance_state'
Exception on /update_problem/233 [POST]
Traceback (most recent call last):
  File "/usr/local/lib/python2.7/dist-packages/flask/app.py", line 1817, in wsgi_app
    response = self.full_dispatch_request()
  File "/usr/local/lib/python2.7/dist-packages/flask/app.py", line 1477, in full_dispatch_request
    rv = self.handle_user_exception(e)
  File "/usr/local/lib/python2.7/dist-packages/flask/app.py", line 1381, in handle_user_exception
    reraise(exc_type, exc_value, tb)
  File "/usr/local/lib/python2.7/dist-packages/flask/app.py", line 1475, in full_dispatch_request
    rv = self.dispatch_request()
  File "/usr/local/lib/python2.7/dist-packages/flask/app.py", line 1461, in dispatch_request
    return self.view_functions[rule.endpoint](**req.view_args)
  File "/usr/local/lib/python2.7/dist-packages/flask_login.py", line 758, in decorated_view
    return func(*args, **kwargs)
  File "/var/www/html/study4share/apps/controllers.py", line 342, in update_problem
    probForm.populate_obj(problem)
  File "/usr/local/lib/python2.7/dist-packages/wtforms/form.py", line 96, in populate_obj
    field.populate_obj(obj, name)
  File "/usr/local/lib/python2.7/dist-packages/wtforms/fields/core.py", line 323, in populate_obj
    setattr(obj, name, self.data)
  File "/usr/local/lib/python2.7/dist-packages/sqlalchemy/orm/attributes.py", line 226, in __set__
    instance_dict(instance), value, None)
  File "/usr/local/lib/python2.7/dist-packages/sqlalchemy/orm/attributes.py", line 812, in set
    value = self.fire_replace_event(state, dict_, value, old, initiator)
  File "/usr/local/lib/python2.7/dist-packages/sqlalchemy/orm/attributes.py", line 832, in fire_replace_event
    state, value, previous, initiator or self._replace_token)
  File "/usr/local/lib/python2.7/dist-packages/sqlalchemy/orm/unitofwork.py", line 84, in set_
    newvalue_state = attributes.instance_state(newvalue)
AttributeError: 'unicode' object has no attribute '_sa_instance_state'
Exception on /update_problem/233 [POST]
Traceback (most recent call last):
  File "/usr/local/lib/python2.7/dist-packages/flask/app.py", line 1817, in wsgi_app
    response = self.full_dispatch_request()
  File "/usr/local/lib/python2.7/dist-packages/flask/app.py", line 1477, in full_dispatch_request
    rv = self.handle_user_exception(e)
  File "/usr/local/lib/python2.7/dist-packages/flask/app.py", line 1381, in handle_user_exception
    reraise(exc_type, exc_value, tb)
  File "/usr/local/lib/python2.7/dist-packages/flask/app.py", line 1475, in full_dispatch_request
    rv = self.dispatch_request()
  File "/usr/local/lib/python2.7/dist-packages/flask/app.py", line 1461, in dispatch_request
    return self.view_functions[rule.endpoint](**req.view_args)
  File "/usr/local/lib/python2.7/dist-packages/flask_login.py", line 758, in decorated_view
    return func(*args, **kwargs)
  File "/var/www/html/study4share/apps/controllers.py", line 342, in update_problem
    probForm.populate_obj(problem)
  File "/usr/local/lib/python2.7/dist-packages/wtforms/form.py", line 96, in populate_obj
    field.populate_obj(obj, name)
  File "/usr/local/lib/python2.7/dist-packages/wtforms/fields/core.py", line 323, in populate_obj
    setattr(obj, name, self.data)
  File "/usr/local/lib/python2.7/dist-packages/sqlalchemy/orm/attributes.py", line 226, in __set__
    instance_dict(instance), value, None)
  File "/usr/local/lib/python2.7/dist-packages/sqlalchemy/orm/attributes.py", line 812, in set
    value = self.fire_replace_event(state, dict_, value, old, initiator)
  File "/usr/local/lib/python2.7/dist-packages/sqlalchemy/orm/attributes.py", line 832, in fire_replace_event
    state, value, previous, initiator or self._replace_token)
  File "/usr/local/lib/python2.7/dist-packages/sqlalchemy/orm/unitofwork.py", line 84, in set_
    newvalue_state = attributes.instance_state(newvalue)
AttributeError: 'unicode' object has no attribute '_sa_instance_state'
Exception on /update_problem/233 [POST]
Traceback (most recent call last):
  File "/usr/local/lib/python2.7/dist-packages/flask/app.py", line 1817, in wsgi_app
    response = self.full_dispatch_request()
  File "/usr/local/lib/python2.7/dist-packages/flask/app.py", line 1477, in full_dispatch_request
    rv = self.handle_user_exception(e)
  File "/usr/local/lib/python2.7/dist-packages/flask/app.py", line 1381, in handle_user_exception
    reraise(exc_type, exc_value, tb)
  File "/usr/local/lib/python2.7/dist-packages/flask/app.py", line 1475, in full_dispatch_request
    rv = self.dispatch_request()
  File "/usr/local/lib/python2.7/dist-packages/flask/app.py", line 1461, in dispatch_request
    return self.view_functions[rule.endpoint](**req.view_args)
  File "/usr/local/lib/python2.7/dist-packages/flask_login.py", line 758, in decorated_view
    return func(*args, **kwargs)
  File "/var/www/html/study4share/apps/controllers.py", line 342, in update_problem
    probForm.populate_obj(problem)
  File "/usr/local/lib/python2.7/dist-packages/wtforms/form.py", line 96, in populate_obj
    field.populate_obj(obj, name)
  File "/usr/local/lib/python2.7/dist-packages/wtforms/fields/core.py", line 323, in populate_obj
    setattr(obj, name, self.data)
  File "/usr/local/lib/python2.7/dist-packages/sqlalchemy/orm/attributes.py", line 226, in __set__
    instance_dict(instance), value, None)
  File "/usr/local/lib/python2.7/dist-packages/sqlalchemy/orm/attributes.py", line 812, in set
    value = self.fire_replace_event(state, dict_, value, old, initiator)
  File "/usr/local/lib/python2.7/dist-packages/sqlalchemy/orm/attributes.py", line 832, in fire_replace_event
    state, value, previous, initiator or self._replace_token)
  File "/usr/local/lib/python2.7/dist-packages/sqlalchemy/orm/unitofwork.py", line 84, in set_
    newvalue_state = attributes.instance_state(newvalue)
AttributeError: 'unicode' object has no attribute '_sa_instance_state'
Exception on /update_problem/233 [POST]
Traceback (most recent call last):
  File "/usr/local/lib/python2.7/dist-packages/flask/app.py", line 1817, in wsgi_app
    response = self.full_dispatch_request()
  File "/usr/local/lib/python2.7/dist-packages/flask/app.py", line 1477, in full_dispatch_request
    rv = self.handle_user_exception(e)
  File "/usr/local/lib/python2.7/dist-packages/flask/app.py", line 1381, in handle_user_exception
    reraise(exc_type, exc_value, tb)
  File "/usr/local/lib/python2.7/dist-packages/flask/app.py", line 1475, in full_dispatch_request
    rv = self.dispatch_request()
  File "/usr/local/lib/python2.7/dist-packages/flask/app.py", line 1461, in dispatch_request
    return self.view_functions[rule.endpoint](**req.view_args)
  File "/usr/local/lib/python2.7/dist-packages/flask_login.py", line 758, in decorated_view
    return func(*args, **kwargs)
  File "/var/www/html/study4share/apps/controllers.py", line 342, in update_problem
    probForm.populate_obj(problem)
  File "/usr/local/lib/python2.7/dist-packages/wtforms/form.py", line 96, in populate_obj
    field.populate_obj(obj, name)
  File "/usr/local/lib/python2.7/dist-packages/wtforms/fields/core.py", line 323, in populate_obj
    setattr(obj, name, self.data)
  File "/usr/local/lib/python2.7/dist-packages/sqlalchemy/orm/attributes.py", line 226, in __set__
    instance_dict(instance), value, None)
  File "/usr/local/lib/python2.7/dist-packages/sqlalchemy/orm/attributes.py", line 812, in set
    value = self.fire_replace_event(state, dict_, value, old, initiator)
  File "/usr/local/lib/python2.7/dist-packages/sqlalchemy/orm/attributes.py", line 832, in fire_replace_event
    state, value, previous, initiator or self._replace_token)
  File "/usr/local/lib/python2.7/dist-packages/sqlalchemy/orm/unitofwork.py", line 84, in set_
    newvalue_state = attributes.instance_state(newvalue)
AttributeError: 'unicode' object has no attribute '_sa_instance_state'
Exception on /main [GET]
Traceback (most recent call last):
  File "/usr/local/lib/python2.7/dist-packages/flask/app.py", line 1817, in wsgi_app
    response = self.full_dispatch_request()
  File "/usr/local/lib/python2.7/dist-packages/flask/app.py", line 1477, in full_dispatch_request
    rv = self.handle_user_exception(e)
  File "/usr/local/lib/python2.7/dist-packages/flask/app.py", line 1381, in handle_user_exception
    reraise(exc_type, exc_value, tb)
  File "/usr/local/lib/python2.7/dist-packages/flask/app.py", line 1475, in full_dispatch_request
    rv = self.dispatch_request()
  File "/usr/local/lib/python2.7/dist-packages/flask/app.py", line 1461, in dispatch_request
    return self.view_functions[rule.endpoint](**req.view_args)
  File "/usr/local/lib/python2.7/dist-packages/flask_login.py", line 758, in decorated_view
    return func(*args, **kwargs)
  File "/var/www/html/study4share/apps/controllers.py", line 166, in main
    return render_template('main.html', form=form, tags=tags, mpmodal_open=False, textcolor=textcolor)
  File "/usr/local/lib/python2.7/dist-packages/flask/templating.py", line 128, in render_template
    context, ctx.app)
  File "/usr/local/lib/python2.7/dist-packages/flask/templating.py", line 110, in _render
    rv = template.render(context)
  File "/usr/local/lib/python2.7/dist-packages/jinja2/environment.py", line 969, in render
    return self.environment.handle_exception(exc_info, True)
  File "/usr/local/lib/python2.7/dist-packages/jinja2/environment.py", line 742, in handle_exception
    reraise(exc_type, exc_value, tb)
  File "/var/www/html/study4share/apps/templates/main.html", line 1, in top-level template code
    {% extends "base.html" %}
  File "/var/www/html/study4share/apps/templates/base.html", line 66, in top-level template code
    {% block content %}{% endblock %}
  File "/var/www/html/study4share/apps/templates/main.html", line 65, in block "content"
    {% include "make_problem.html" %}
  File "/var/www/html/study4share/apps/templates/make_problem.html", line 20, in top-level template code
    <span style="color:skyblue; font-weight:bold; font-size:3em;">{{form.tag.label}}</span>
  File "/usr/local/lib/python2.7/dist-packages/jinja2/environment.py", line 397, in getattr
    return getattr(obj, attribute)
UndefinedError: 'apps.forms.ProblemForm object' has no attribute 'tag'
Exception on /problem_list/study4share/  [GET]
Traceback (most recent call last):
  File "/usr/local/lib/python2.7/dist-packages/flask/app.py", line 1817, in wsgi_app
    response = self.full_dispatch_request()
  File "/usr/local/lib/python2.7/dist-packages/flask/app.py", line 1477, in full_dispatch_request
    rv = self.handle_user_exception(e)
  File "/usr/local/lib/python2.7/dist-packages/flask/app.py", line 1381, in handle_user_exception
    reraise(exc_type, exc_value, tb)
  File "/usr/local/lib/python2.7/dist-packages/flask/app.py", line 1475, in full_dispatch_request
    rv = self.dispatch_request()
  File "/usr/local/lib/python2.7/dist-packages/flask/app.py", line 1461, in dispatch_request
    return self.view_functions[rule.endpoint](**req.view_args)
  File "/usr/local/lib/python2.7/dist-packages/flask_login.py", line 758, in decorated_view
    return func(*args, **kwargs)
  File "/var/www/html/study4share/apps/controllers.py", line 227, in problem_list
    dict_for_flist[key].append(prob)
KeyError: u'\ud574\uacb0'
Exception on /update_problem/216 [POST]
Traceback (most recent call last):
  File "/usr/local/lib/python2.7/dist-packages/flask/app.py", line 1817, in wsgi_app
    response = self.full_dispatch_request()
  File "/usr/local/lib/python2.7/dist-packages/flask/app.py", line 1477, in full_dispatch_request
    rv = self.handle_user_exception(e)
  File "/usr/local/lib/python2.7/dist-packages/flask/app.py", line 1381, in handle_user_exception
    reraise(exc_type, exc_value, tb)
  File "/usr/local/lib/python2.7/dist-packages/flask/app.py", line 1475, in full_dispatch_request
    rv = self.dispatch_request()
  File "/usr/local/lib/python2.7/dist-packages/flask/app.py", line 1461, in dispatch_request
    return self.view_functions[rule.endpoint](**req.view_args)
  File "/usr/local/lib/python2.7/dist-packages/flask_login.py", line 758, in decorated_view
    return func(*args, **kwargs)
  File "/var/www/html/study4share/apps/controllers.py", line 385, in update_problem
    sortlist.remove(old_key)
ValueError: list.remove(x): x not in list
Exception on /update_problem/216 [POST]
Traceback (most recent call last):
  File "/usr/local/lib/python2.7/dist-packages/flask/app.py", line 1817, in wsgi_app
    response = self.full_dispatch_request()
  File "/usr/local/lib/python2.7/dist-packages/flask/app.py", line 1477, in full_dispatch_request
    rv = self.handle_user_exception(e)
  File "/usr/local/lib/python2.7/dist-packages/flask/app.py", line 1381, in handle_user_exception
    reraise(exc_type, exc_value, tb)
  File "/usr/local/lib/python2.7/dist-packages/flask/app.py", line 1475, in full_dispatch_request
    rv = self.dispatch_request()
  File "/usr/local/lib/python2.7/dist-packages/flask/app.py", line 1461, in dispatch_request
    return self.view_functions[rule.endpoint](**req.view_args)
  File "/usr/local/lib/python2.7/dist-packages/flask_login.py", line 758, in decorated_view
    return func(*args, **kwargs)
  File "/var/www/html/study4share/apps/controllers.py", line 385, in update_problem
    sortlist.remove(old_key)
ValueError: list.remove(x): x not in list
Exception on /update_problem/216 [POST]
Traceback (most recent call last):
  File "/usr/local/lib/python2.7/dist-packages/flask/app.py", line 1817, in wsgi_app
    response = self.full_dispatch_request()
  File "/usr/local/lib/python2.7/dist-packages/flask/app.py", line 1477, in full_dispatch_request
    rv = self.handle_user_exception(e)
  File "/usr/local/lib/python2.7/dist-packages/flask/app.py", line 1381, in handle_user_exception
    reraise(exc_type, exc_value, tb)
  File "/usr/local/lib/python2.7/dist-packages/flask/app.py", line 1475, in full_dispatch_request
    rv = self.dispatch_request()
  File "/usr/local/lib/python2.7/dist-packages/flask/app.py", line 1461, in dispatch_request
    return self.view_functions[rule.endpoint](**req.view_args)
  File "/usr/local/lib/python2.7/dist-packages/flask_login.py", line 758, in decorated_view
    return func(*args, **kwargs)
  File "/var/www/html/study4share/apps/controllers.py", line 385, in update_problem
    sortlist.remove(old_key)
ValueError: list.remove(x): x not in list
Exception on /update_problem/236 [POST]
Traceback (most recent call last):
  File "/usr/local/lib/python2.7/dist-packages/flask/app.py", line 1817, in wsgi_app
    response = self.full_dispatch_request()
  File "/usr/local/lib/python2.7/dist-packages/flask/app.py", line 1477, in full_dispatch_request
    rv = self.handle_user_exception(e)
  File "/usr/local/lib/python2.7/dist-packages/flask/app.py", line 1381, in handle_user_exception
    reraise(exc_type, exc_value, tb)
  File "/usr/local/lib/python2.7/dist-packages/flask/app.py", line 1475, in full_dispatch_request
    rv = self.dispatch_request()
  File "/usr/local/lib/python2.7/dist-packages/flask/app.py", line 1461, in dispatch_request
    return self.view_functions[rule.endpoint](**req.view_args)
  File "/usr/local/lib/python2.7/dist-packages/flask_login.py", line 758, in decorated_view
    return func(*args, **kwargs)
  File "/var/www/html/study4share/apps/controllers.py", line 337, in update_problem
    if problem.user_id != g.user.id:
UnboundLocalError: local variable 'problem' referenced before assignment
Exception on /update_problem/236 [POST]
Traceback (most recent call last):
  File "/usr/local/lib/python2.7/dist-packages/flask/app.py", line 1817, in wsgi_app
    response = self.full_dispatch_request()
  File "/usr/local/lib/python2.7/dist-packages/flask/app.py", line 1477, in full_dispatch_request
    rv = self.handle_user_exception(e)
  File "/usr/local/lib/python2.7/dist-packages/flask/app.py", line 1381, in handle_user_exception
    reraise(exc_type, exc_value, tb)
  File "/usr/local/lib/python2.7/dist-packages/flask/app.py", line 1475, in full_dispatch_request
    rv = self.dispatch_request()
  File "/usr/local/lib/python2.7/dist-packages/flask/app.py", line 1461, in dispatch_request
    return self.view_functions[rule.endpoint](**req.view_args)
  File "/usr/local/lib/python2.7/dist-packages/flask_login.py", line 758, in decorated_view
    return func(*args, **kwargs)
  File "/var/www/html/study4share/apps/controllers.py", line 337, in update_problem
    if problem.user_id != g.user.id:
UnboundLocalError: local variable 'problem' referenced before assignment
Exception on /add/폰번호/점수 [GET]
Traceback (most recent call last):
  File "/usr/local/lib/python2.7/dist-packages/flask/app.py", line 1817, in wsgi_app
    response = self.full_dispatch_request()
  File "/usr/local/lib/python2.7/dist-packages/flask/app.py", line 1477, in full_dispatch_request
    rv = self.handle_user_exception(e)
  File "/usr/local/lib/python2.7/dist-packages/flask/app.py", line 1381, in handle_user_exception
    reraise(exc_type, exc_value, tb)
  File "/usr/local/lib/python2.7/dist-packages/flask/app.py", line 1475, in full_dispatch_request
    rv = self.dispatch_request()
  File "/usr/local/lib/python2.7/dist-packages/flask/app.py", line 1461, in dispatch_request
    return self.view_functions[rule.endpoint](**req.view_args)
  File "/var/www/html/study4share/apps/controllers.py", line 699, in upload_db
    db.session.commit()
  File "/usr/local/lib/python2.7/dist-packages/sqlalchemy/orm/scoping.py", line 150, in do
    return getattr(self.registry(), name)(*args, **kwargs)
  File "/usr/local/lib/python2.7/dist-packages/sqlalchemy/orm/session.py", line 788, in commit
    self.transaction.commit()
  File "/usr/local/lib/python2.7/dist-packages/sqlalchemy/orm/session.py", line 384, in commit
    self._prepare_impl()
  File "/usr/local/lib/python2.7/dist-packages/sqlalchemy/orm/session.py", line 364, in _prepare_impl
    self.session.flush()
  File "/usr/local/lib/python2.7/dist-packages/sqlalchemy/orm/session.py", line 1985, in flush
    self._flush(objects)
  File "/usr/local/lib/python2.7/dist-packages/sqlalchemy/orm/session.py", line 2103, in _flush
    transaction.rollback(_capture_exception=True)
  File "/usr/local/lib/python2.7/dist-packages/sqlalchemy/util/langhelpers.py", line 60, in __exit__
    compat.reraise(exc_type, exc_value, exc_tb)
  File "/usr/local/lib/python2.7/dist-packages/sqlalchemy/orm/session.py", line 2067, in _flush
    flush_context.execute()
  File "/usr/local/lib/python2.7/dist-packages/sqlalchemy/orm/unitofwork.py", line 372, in execute
    rec.execute(self)
  File "/usr/local/lib/python2.7/dist-packages/sqlalchemy/orm/unitofwork.py", line 526, in execute
    uow
  File "/usr/local/lib/python2.7/dist-packages/sqlalchemy/orm/persistence.py", line 65, in save_obj
    mapper, table, insert)
  File "/usr/local/lib/python2.7/dist-packages/sqlalchemy/orm/persistence.py", line 570, in _emit_insert_statements
    execute(statement, multiparams)
  File "/usr/local/lib/python2.7/dist-packages/sqlalchemy/engine/base.py", line 841, in execute
    return meth(self, multiparams, params)
  File "/usr/local/lib/python2.7/dist-packages/sqlalchemy/sql/elements.py", line 322, in _execute_on_connection
    return connection._execute_clauseelement(self, multiparams, params)
  File "/usr/local/lib/python2.7/dist-packages/sqlalchemy/engine/base.py", line 938, in _execute_clauseelement
    compiled_sql, distilled_params
  File "/usr/local/lib/python2.7/dist-packages/sqlalchemy/engine/base.py", line 1070, in _execute_context
    context)
  File "/usr/local/lib/python2.7/dist-packages/sqlalchemy/engine/base.py", line 1274, in _handle_dbapi_exception
    util.reraise(*exc_info)
  File "/usr/local/lib/python2.7/dist-packages/sqlalchemy/engine/base.py", line 1063, in _execute_context
    context)
  File "/usr/local/lib/python2.7/dist-packages/sqlalchemy/engine/default.py", line 442, in do_execute
    cursor.execute(statement, parameters)
  File "/usr/lib/python2.7/dist-packages/MySQLdb/cursors.py", line 176, in execute
    if not self._defer_warnings: self._warning_check()
  File "/usr/lib/python2.7/dist-packages/MySQLdb/cursors.py", line 92, in _warning_check
    warn(w[-1], self.Warning, 3)
  File "/usr/lib/python2.7/warnings.py", line 29, in _show_warning
    file.write(formatwarning(message, category, filename, lineno, line))
  File "/usr/lib/python2.7/warnings.py", line 38, in formatwarning
    s =  "%s:%s: %s: %s\n" % (filename, lineno, category.__name__, message)
UnicodeEncodeError: 'ascii' codec can't encode characters in position 26-27: ordinal not in range(128)
Exception on /login [GET]
Traceback (most recent call last):
  File "/usr/local/lib/python2.7/dist-packages/flask/app.py", line 1817, in wsgi_app
    response = self.full_dispatch_request()
  File "/usr/local/lib/python2.7/dist-packages/flask/app.py", line 1477, in full_dispatch_request
    rv = self.handle_user_exception(e)
  File "/usr/local/lib/python2.7/dist-packages/flask/app.py", line 1381, in handle_user_exception
    reraise(exc_type, exc_value, tb)
  File "/usr/local/lib/python2.7/dist-packages/flask/app.py", line 1475, in full_dispatch_request
    rv = self.dispatch_request()
  File "/usr/local/lib/python2.7/dist-packages/flask/app.py", line 1461, in dispatch_request
    return self.view_functions[rule.endpoint](**req.view_args)
  File "/var/www/html/study4share/apps/controllers.py", line 72, in login
    @app.route('/login/facebook/authorized')
  File "/usr/local/lib/python2.7/dist-packages/flask/templating.py", line 127, in render_template
    return _render(ctx.app.jinja_env.get_or_select_template(template_name_or_list),
  File "/usr/local/lib/python2.7/dist-packages/jinja2/environment.py", line 830, in get_or_select_template
    return self.get_template(template_name_or_list, parent, globals)
  File "/usr/local/lib/python2.7/dist-packages/jinja2/environment.py", line 791, in get_template
    return self._load_template(name, self.make_globals(globals))
  File "/usr/local/lib/python2.7/dist-packages/jinja2/environment.py", line 765, in _load_template
    template = self.loader.load(self, name, globals)
  File "/usr/local/lib/python2.7/dist-packages/jinja2/loaders.py", line 113, in load
    source, filename, uptodate = self.get_source(environment, name)
  File "/usr/local/lib/python2.7/dist-packages/flask/templating.py", line 64, in get_source
    raise TemplateNotFound(template)
TemplateNotFound: login.html
Exception on /login [GET]
Traceback (most recent call last):
  File "/usr/local/lib/python2.7/dist-packages/flask/app.py", line 1817, in wsgi_app
    response = self.full_dispatch_request()
  File "/usr/local/lib/python2.7/dist-packages/flask/app.py", line 1477, in full_dispatch_request
    rv = self.handle_user_exception(e)
  File "/usr/local/lib/python2.7/dist-packages/flask/app.py", line 1381, in handle_user_exception
    reraise(exc_type, exc_value, tb)
  File "/usr/local/lib/python2.7/dist-packages/flask/app.py", line 1475, in full_dispatch_request
    rv = self.dispatch_request()
  File "/usr/local/lib/python2.7/dist-packages/flask/app.py", line 1461, in dispatch_request
    return self.view_functions[rule.endpoint](**req.view_args)
  File "/var/www/html/study4share/apps/controllers.py", line 72, in login
    @app.route('/login/facebook/authorized')
  File "/usr/local/lib/python2.7/dist-packages/flask/templating.py", line 127, in render_template
    return _render(ctx.app.jinja_env.get_or_select_template(template_name_or_list),
  File "/usr/local/lib/python2.7/dist-packages/jinja2/environment.py", line 830, in get_or_select_template
    return self.get_template(template_name_or_list, parent, globals)
  File "/usr/local/lib/python2.7/dist-packages/jinja2/environment.py", line 791, in get_template
    return self._load_template(name, self.make_globals(globals))
  File "/usr/local/lib/python2.7/dist-packages/jinja2/environment.py", line 765, in _load_template
    template = self.loader.load(self, name, globals)
  File "/usr/local/lib/python2.7/dist-packages/jinja2/loaders.py", line 113, in load
    source, filename, uptodate = self.get_source(environment, name)
  File "/usr/local/lib/python2.7/dist-packages/flask/templating.py", line 64, in get_source
    raise TemplateNotFound(template)
TemplateNotFound: login.html
Exception on /login [GET]
Traceback (most recent call last):
  File "/usr/local/lib/python2.7/dist-packages/flask/app.py", line 1817, in wsgi_app
    response = self.full_dispatch_request()
  File "/usr/local/lib/python2.7/dist-packages/flask/app.py", line 1477, in full_dispatch_request
    rv = self.handle_user_exception(e)
  File "/usr/local/lib/python2.7/dist-packages/flask/app.py", line 1381, in handle_user_exception
    reraise(exc_type, exc_value, tb)
  File "/usr/local/lib/python2.7/dist-packages/flask/app.py", line 1475, in full_dispatch_request
    rv = self.dispatch_request()
  File "/usr/local/lib/python2.7/dist-packages/flask/app.py", line 1461, in dispatch_request
    return self.view_functions[rule.endpoint](**req.view_args)
  File "/var/www/html/study4share/apps/controllers.py", line 72, in login
    @app.route('/login/facebook/authorized')
  File "/usr/local/lib/python2.7/dist-packages/flask/templating.py", line 127, in render_template
    return _render(ctx.app.jinja_env.get_or_select_template(template_name_or_list),
  File "/usr/local/lib/python2.7/dist-packages/jinja2/environment.py", line 830, in get_or_select_template
    return self.get_template(template_name_or_list, parent, globals)
  File "/usr/local/lib/python2.7/dist-packages/jinja2/environment.py", line 791, in get_template
    return self._load_template(name, self.make_globals(globals))
  File "/usr/local/lib/python2.7/dist-packages/jinja2/environment.py", line 765, in _load_template
    template = self.loader.load(self, name, globals)
  File "/usr/local/lib/python2.7/dist-packages/jinja2/loaders.py", line 113, in load
    source, filename, uptodate = self.get_source(environment, name)
  File "/usr/local/lib/python2.7/dist-packages/flask/templating.py", line 64, in get_source
    raise TemplateNotFound(template)
TemplateNotFound: login.html
Exception on /login [GET]
Traceback (most recent call last):
  File "/usr/local/lib/python2.7/dist-packages/flask/app.py", line 1817, in wsgi_app
    response = self.full_dispatch_request()
  File "/usr/local/lib/python2.7/dist-packages/flask/app.py", line 1477, in full_dispatch_request
    rv = self.handle_user_exception(e)
  File "/usr/local/lib/python2.7/dist-packages/flask/app.py", line 1381, in handle_user_exception
    reraise(exc_type, exc_value, tb)
  File "/usr/local/lib/python2.7/dist-packages/flask/app.py", line 1475, in full_dispatch_request
    rv = self.dispatch_request()
  File "/usr/local/lib/python2.7/dist-packages/flask/app.py", line 1461, in dispatch_request
    return self.view_functions[rule.endpoint](**req.view_args)
  File "/var/www/html/study4share/apps/controllers.py", line 72, in login
    @app.route('/login/facebook/authorized')
  File "/usr/local/lib/python2.7/dist-packages/flask/templating.py", line 127, in render_template
    return _render(ctx.app.jinja_env.get_or_select_template(template_name_or_list),
  File "/usr/local/lib/python2.7/dist-packages/jinja2/environment.py", line 830, in get_or_select_template
    return self.get_template(template_name_or_list, parent, globals)
  File "/usr/local/lib/python2.7/dist-packages/jinja2/environment.py", line 791, in get_template
    return self._load_template(name, self.make_globals(globals))
  File "/usr/local/lib/python2.7/dist-packages/jinja2/environment.py", line 765, in _load_template
    template = self.loader.load(self, name, globals)
  File "/usr/local/lib/python2.7/dist-packages/jinja2/loaders.py", line 113, in load
    source, filename, uptodate = self.get_source(environment, name)
  File "/usr/local/lib/python2.7/dist-packages/flask/templating.py", line 64, in get_source
    raise TemplateNotFound(template)
TemplateNotFound: login.html
Exception on /add/폰번호/점수 [GET]
Traceback (most recent call last):
  File "/usr/local/lib/python2.7/dist-packages/flask/app.py", line 1817, in wsgi_app
    response = self.full_dispatch_request()
  File "/usr/local/lib/python2.7/dist-packages/flask/app.py", line 1477, in full_dispatch_request
    rv = self.handle_user_exception(e)
  File "/usr/local/lib/python2.7/dist-packages/flask/app.py", line 1381, in handle_user_exception
    reraise(exc_type, exc_value, tb)
  File "/usr/local/lib/python2.7/dist-packages/flask/app.py", line 1475, in full_dispatch_request
    rv = self.dispatch_request()
  File "/usr/local/lib/python2.7/dist-packages/flask/app.py", line 1461, in dispatch_request
    return self.view_functions[rule.endpoint](**req.view_args)
  File "/var/www/html/study4share/apps/controllers.py", line 699, in upload_db
    db.session.commit()
  File "/usr/local/lib/python2.7/dist-packages/sqlalchemy/orm/scoping.py", line 150, in do
    return getattr(self.registry(), name)(*args, **kwargs)
  File "/usr/local/lib/python2.7/dist-packages/sqlalchemy/orm/session.py", line 788, in commit
    self.transaction.commit()
  File "/usr/local/lib/python2.7/dist-packages/sqlalchemy/orm/session.py", line 384, in commit
    self._prepare_impl()
  File "/usr/local/lib/python2.7/dist-packages/sqlalchemy/orm/session.py", line 364, in _prepare_impl
    self.session.flush()
  File "/usr/local/lib/python2.7/dist-packages/sqlalchemy/orm/session.py", line 1985, in flush
    self._flush(objects)
  File "/usr/local/lib/python2.7/dist-packages/sqlalchemy/orm/session.py", line 2103, in _flush
    transaction.rollback(_capture_exception=True)
  File "/usr/local/lib/python2.7/dist-packages/sqlalchemy/util/langhelpers.py", line 60, in __exit__
    compat.reraise(exc_type, exc_value, exc_tb)
  File "/usr/local/lib/python2.7/dist-packages/sqlalchemy/orm/session.py", line 2067, in _flush
    flush_context.execute()
  File "/usr/local/lib/python2.7/dist-packages/sqlalchemy/orm/unitofwork.py", line 372, in execute
    rec.execute(self)
  File "/usr/local/lib/python2.7/dist-packages/sqlalchemy/orm/unitofwork.py", line 526, in execute
    uow
  File "/usr/local/lib/python2.7/dist-packages/sqlalchemy/orm/persistence.py", line 65, in save_obj
    mapper, table, insert)
  File "/usr/local/lib/python2.7/dist-packages/sqlalchemy/orm/persistence.py", line 570, in _emit_insert_statements
    execute(statement, multiparams)
  File "/usr/local/lib/python2.7/dist-packages/sqlalchemy/engine/base.py", line 841, in execute
    return meth(self, multiparams, params)
  File "/usr/local/lib/python2.7/dist-packages/sqlalchemy/sql/elements.py", line 322, in _execute_on_connection
    return connection._execute_clauseelement(self, multiparams, params)
  File "/usr/local/lib/python2.7/dist-packages/sqlalchemy/engine/base.py", line 938, in _execute_clauseelement
    compiled_sql, distilled_params
  File "/usr/local/lib/python2.7/dist-packages/sqlalchemy/engine/base.py", line 1070, in _execute_context
    context)
  File "/usr/local/lib/python2.7/dist-packages/sqlalchemy/engine/base.py", line 1274, in _handle_dbapi_exception
    util.reraise(*exc_info)
  File "/usr/local/lib/python2.7/dist-packages/sqlalchemy/engine/base.py", line 1063, in _execute_context
    context)
  File "/usr/local/lib/python2.7/dist-packages/sqlalchemy/engine/default.py", line 442, in do_execute
    cursor.execute(statement, parameters)
  File "/usr/lib/python2.7/dist-packages/MySQLdb/cursors.py", line 176, in execute
    if not self._defer_warnings: self._warning_check()
  File "/usr/lib/python2.7/dist-packages/MySQLdb/cursors.py", line 92, in _warning_check
    warn(w[-1], self.Warning, 3)
  File "/usr/lib/python2.7/warnings.py", line 29, in _show_warning
    file.write(formatwarning(message, category, filename, lineno, line))
  File "/usr/lib/python2.7/warnings.py", line 38, in formatwarning
    s =  "%s:%s: %s: %s\n" % (filename, lineno, category.__name__, message)
UnicodeEncodeError: 'ascii' codec can't encode characters in position 26-27: ordinal not in range(128)
Exception on /login [GET]
Traceback (most recent call last):
  File "/usr/local/lib/python2.7/dist-packages/flask/app.py", line 1817, in wsgi_app
    response = self.full_dispatch_request()
  File "/usr/local/lib/python2.7/dist-packages/flask/app.py", line 1477, in full_dispatch_request
    rv = self.handle_user_exception(e)
  File "/usr/local/lib/python2.7/dist-packages/flask/app.py", line 1381, in handle_user_exception
    reraise(exc_type, exc_value, tb)
  File "/usr/local/lib/python2.7/dist-packages/flask/app.py", line 1475, in full_dispatch_request
    rv = self.dispatch_request()
  File "/usr/local/lib/python2.7/dist-packages/flask/app.py", line 1461, in dispatch_request
    return self.view_functions[rule.endpoint](**req.view_args)
  File "/var/www/html/study4share/apps/controllers.py", line 72, in login
    
  File "/usr/local/lib/python2.7/dist-packages/flask/templating.py", line 127, in render_template
    return _render(ctx.app.jinja_env.get_or_select_template(template_name_or_list),
  File "/usr/local/lib/python2.7/dist-packages/jinja2/environment.py", line 830, in get_or_select_template
    return self.get_template(template_name_or_list, parent, globals)
  File "/usr/local/lib/python2.7/dist-packages/jinja2/environment.py", line 791, in get_template
    return self._load_template(name, self.make_globals(globals))
  File "/usr/local/lib/python2.7/dist-packages/jinja2/environment.py", line 765, in _load_template
    template = self.loader.load(self, name, globals)
  File "/usr/local/lib/python2.7/dist-packages/jinja2/loaders.py", line 113, in load
    source, filename, uptodate = self.get_source(environment, name)
  File "/usr/local/lib/python2.7/dist-packages/flask/templating.py", line 64, in get_source
    raise TemplateNotFound(template)
TemplateNotFound: login.html
